<?xml version="1.0" ?>
<robot name="quadruped" xmlns:xacro="http://www.ros.org/wiki/xacro">

<xacro:macro name="quadruped" params="prefix load_meta:=true">

<xacro:if value="${load_meta}">
  <xacro:include filename="$(find quadruped_description)/urdf/materials.xacro" />
  <xacro:include filename="$(find quadruped_description)/urdf/quadruped.trans" />
  <xacro:include filename="$(find quadruped_description)/urdf/quadruped.gazebo" />
</xacro:if>

<link name="${prefix}base_link"/>

<link name="${prefix}fr_leg">
  <inertial>
    <origin xyz="0.2794659077094293 0.10955136812865379 0.06129728585412236" rpy="0 0 0"/>
    <mass value="0.8819417369199037"/>
    <inertia ixx="0.001237" iyy="0.001149" izz="0.000204" ixy="3e-06" iyz="-5e-05" ixz="2.2e-05"/>
  </inertial>
  <visual>
    <origin xyz="0 0 0" rpy="0 0 0"/>
    <geometry>
      <mesh filename="package://quadruped_description/meshes/fr_leg.stl" scale="0.001 0.001 0.001"/>
    </geometry>
    <material name="quadruped_silver"/>
  </visual>
  <collision>
    <origin xyz="0 0 0" rpy="0 0 0"/>
    <geometry>
      <mesh filename="package://quadruped_description/meshes/fr_leg.stl" scale="0.001 0.001 0.001"/>
    </geometry>
  </collision>
</link>

<link name="${prefix}fr_foot">
  <inertial>
    <origin xyz="0.25012187160177024 0.08769471310176047 0.05479856375575117" rpy="0 0 0"/>
    <mass value="0.4701549157206577"/>
    <inertia ixx="0.000959" iyy="0.000946" izz="7e-05" ixy="-3e-06" iyz="1.5e-05" ixz="2.6e-05"/>
  </inertial>
  <visual>
    <origin xyz="0 0 0" rpy="0 0 0"/>
    <geometry>
      <mesh filename="package://quadruped_description/meshes/fr_foot.stl" scale="0.001 0.001 0.001"/>
    </geometry>
    <material name="quadruped_silver"/>
  </visual>
  <collision>
    <origin xyz="0 0 0" rpy="0 0 0"/>
    <geometry>
      <mesh filename="package://quadruped_description/meshes/fr_foot.stl" scale="0.001 0.001 0.001"/>
    </geometry>
  </collision>
</link>

<link name="${prefix}rr_hip">
  <inertial>
    <origin xyz="0.025791133699816296 -0.005806493712104371 -0.01070416517682482" rpy="0 0 0"/>
    <mass value="0.43930544603172716"/>
    <inertia ixx="0.000128" iyy="0.000144" izz="9.8e-05" ixy="1e-06" iyz="-0.0" ixz="1e-06"/>
  </inertial>
  <visual>
    <origin xyz="0 0 0" rpy="0 0 0"/>
    <geometry>
      <mesh filename="package://quadruped_description/meshes/rr_hip.stl" scale="0.001 0.001 0.001"/>
    </geometry>
    <material name="quadruped_silver"/>
  </visual>
  <collision>
    <origin xyz="0 0 0" rpy="0 0 0"/>
    <geometry>
      <mesh filename="package://quadruped_description/meshes/rr_hip.stl" scale="0.001 0.001 0.001"/>
    </geometry>
  </collision>
</link>

<link name="${prefix}rr_leg">
  <inertial>
    <origin xyz="0.04626645178615444 0.10957766231895688 0.05997899635407573" rpy="0 0 0"/>
    <mass value="0.8819417369199037"/>
    <inertia ixx="0.001237" iyy="0.001149" izz="0.000204" ixy="3e-06" iyz="-5e-05" ixz="2.2e-05"/>
  </inertial>
  <visual>
    <origin xyz="0 0 0" rpy="0 0 0"/>
    <geometry>
      <mesh filename="package://quadruped_description/meshes/rr_leg.stl" scale="0.001 0.001 0.001"/>
    </geometry>
    <material name="quadruped_silver"/>
  </visual>
  <collision>
    <origin xyz="0 0 0" rpy="0 0 0"/>
    <geometry>
      <mesh filename="package://quadruped_description/meshes/rr_leg.stl" scale="0.001 0.001 0.001"/>
    </geometry>
  </collision>
</link>

<link name="${prefix}rr_foot">
  <inertial>
    <origin xyz="0.06841847324239722 0.0905460609971834 0.054000498607300655" rpy="0 0 0"/>
    <mass value="0.4701549157206577"/>
    <inertia ixx="0.000959" iyy="0.000946" izz="7e-05" ixy="-3e-06" iyz="1.5e-05" ixz="2.6e-05"/>
  </inertial>
  <visual>
    <origin xyz="0 0 0" rpy="0 0 0"/>
    <geometry>
      <mesh filename="package://quadruped_description/meshes/rr_foot.stl" scale="0.001 0.001 0.001"/>
    </geometry>
    <material name="quadruped_silver"/>
  </visual>
  <collision>
    <origin xyz="0 0 0" rpy="0 0 0"/>
    <geometry>
      <mesh filename="package://quadruped_description/meshes/rr_foot.stl" scale="0.001 0.001 0.001"/>
    </geometry>
  </collision>
</link>

<link name="${prefix}fl_hip">
  <inertial>
    <origin xyz="-0.025557072425756333 0.005789983463523024 -0.011262075766518248" rpy="0 0 0"/>
    <mass value="0.43930544603256694"/>
    <inertia ixx="0.000129" iyy="0.000144" izz="9.8e-05" ixy="1e-06" iyz="0.0" ixz="-1e-06"/>
  </inertial>
  <visual>
    <origin xyz="0 0 0" rpy="0 0 0"/>
    <geometry>
      <mesh filename="package://quadruped_description/meshes/fl_hip.stl" scale="0.001 0.001 0.001"/>
    </geometry>
    <material name="quadruped_silver"/>
  </visual>
  <collision>
    <origin xyz="0 0 0" rpy="0 0 0"/>
    <geometry>
      <mesh filename="package://quadruped_description/meshes/fl_hip.stl" scale="0.001 0.001 0.001"/>
    </geometry>
  </collision>
</link>

<link name="${prefix}rl_hip">
  <inertial>
    <origin xyz="0.026321801727345273 0.005850566955009157 -0.010724939529368746" rpy="0 0 0"/>
    <mass value="0.44027574194204244"/>
    <inertia ixx="0.000129" iyy="0.000143" izz="9.8e-05" ixy="-1e-06" iyz="0.0" ixz="1e-06"/>
  </inertial>
  <visual>
    <origin xyz="0 0 0" rpy="0 0 0"/>
    <geometry>
      <mesh filename="package://quadruped_description/meshes/rl_hip.stl" scale="0.001 0.001 0.001"/>
    </geometry>
    <material name="quadruped_silver"/>
  </visual>
  <collision>
    <origin xyz="0 0 0" rpy="0 0 0"/>
    <geometry>
      <mesh filename="package://quadruped_description/meshes/rl_hip.stl" scale="0.001 0.001 0.001"/>
    </geometry>
  </collision>
</link>

<link name="${prefix}fl_leg">
  <inertial>
    <origin xyz="0.2831914983037829 0.24126830447985162 0.061038983786785" rpy="0 0 0"/>
    <mass value="0.8798800717218304"/>
    <inertia ixx="0.00123" iyy="0.001145" izz="0.0002" ixy="-4e-06" iyz="4.8e-05" ixz="2.8e-05"/>
  </inertial>
  <visual>
    <origin xyz="0 0 0" rpy="0 0 0"/>
    <geometry>
      <mesh filename="package://quadruped_description/meshes/fl_leg.stl" scale="0.001 0.001 0.001"/>
    </geometry>
    <material name="quadruped_silver"/>
  </visual>
  <collision>
    <origin xyz="0 0 0" rpy="0 0 0"/>
    <geometry>
      <mesh filename="package://quadruped_description/meshes/fl_leg.stl" scale="0.001 0.001 0.001"/>
    </geometry>
  </collision>
</link>

<link name="${prefix}rl_leg">
  <inertial>
    <origin xyz="0.04658350461950634 0.24126777959658083 0.059724516134193446" rpy="0 0 0"/>
    <mass value="0.8798800717218304"/>
    <inertia ixx="0.00123" iyy="0.001145" izz="0.0002" ixy="-4e-06" iyz="4.8e-05" ixz="2.8e-05"/>
  </inertial>
  <visual>
    <origin xyz="0 0 0" rpy="0 0 0"/>
    <geometry>
      <mesh filename="package://quadruped_description/meshes/rl_leg.stl" scale="0.001 0.001 0.001"/>
    </geometry>
    <material name="quadruped_silver"/>
  </visual>
  <collision>
    <origin xyz="0 0 0" rpy="0 0 0"/>
    <geometry>
      <mesh filename="package://quadruped_description/meshes/rl_leg.stl" scale="0.001 0.001 0.001"/>
    </geometry>
  </collision>
</link>

<link name="${prefix}fl_foot">
  <inertial>
    <origin xyz="0.2540348261083457 0.26058873967984747 0.054752808825988375" rpy="0 0 0"/>
    <mass value="0.4874391356623863"/>
    <inertia ixx="0.000995" iyy="0.00098" izz="7.3e-05" ixy="3e-06" iyz="-2e-05" ixz="2.7e-05"/>
  </inertial>
  <visual>
    <origin xyz="0 0 0" rpy="0 0 0"/>
    <geometry>
      <mesh filename="package://quadruped_description/meshes/fl_foot.stl" scale="0.001 0.001 0.001"/>
    </geometry>
    <material name="quadruped_silver"/>
  </visual>
  <collision>
    <origin xyz="0 0 0" rpy="0 0 0"/>
    <geometry>
      <mesh filename="package://quadruped_description/meshes/fl_foot.stl" scale="0.001 0.001 0.001"/>
    </geometry>
  </collision>
</link>

<link name="${prefix}rl_foot">
  <inertial>
    <origin xyz="0.06892183242406924 0.26341421479657695 0.054013341173396755" rpy="0 0 0"/>
    <mass value="0.4874391356623863"/>
    <inertia ixx="0.000995" iyy="0.00098" izz="7.3e-05" ixy="3e-06" iyz="-2e-05" ixz="2.7e-05"/>
  </inertial>
  <visual>
    <origin xyz="0 0 0" rpy="0 0 0"/>
    <geometry>
      <mesh filename="package://quadruped_description/meshes/rl_foot.stl" scale="0.001 0.001 0.001"/>
    </geometry>
    <material name="quadruped_silver"/>
  </visual>
  <collision>
    <origin xyz="0 0 0" rpy="0 0 0"/>
    <geometry>
      <mesh filename="package://quadruped_description/meshes/rl_foot.stl" scale="0.001 0.001 0.001"/>
    </geometry>
  </collision>
</link>

<link name="${prefix}fr_hip">
  <inertial>
    <origin xyz="-0.026087324689042568 -0.005866966001807389 -0.011274777196066912" rpy="0 0 0"/>
    <mass value="0.4402757419432759"/>
    <inertia ixx="0.000129" iyy="0.000143" izz="9.8e-05" ixy="-1e-06" iyz="-0.0" ixz="-0.0"/>
  </inertial>
  <visual>
    <origin xyz="0 0 0" rpy="0 0 0"/>
    <geometry>
      <mesh filename="package://quadruped_description/meshes/fr_hip.stl" scale="0.001 0.001 0.001"/>
    </geometry>
    <material name="quadruped_silver"/>
  </visual>
  <collision>
    <origin xyz="0 0 0" rpy="0 0 0"/>
    <geometry>
      <mesh filename="package://quadruped_description/meshes/fr_hip.stl" scale="0.001 0.001 0.001"/>
    </geometry>
  </collision>
</link>

<joint name="${prefix}fr_o_hip" type="revolute">
  <origin xyz="-0.025887 -0.027214 -0.011343" rpy="0.0 -0.0 0.0"/>
  <parent link="${prefix}fr_hip"/>
  <child link="${prefix}fr_leg"/>
  <axis xyz="-4e-06 -1.0 0.000781"/>
  <limit upper="0.785398" lower="-0.785398" effort="100" velocity="100"/>
</joint>

<joint name="${prefix}fr_knee" type="continuous">
  <origin xyz="0.01628 -0.002284 -0.107564" rpy="0.0 -0.0 0.0"/>
  <parent link="${prefix}fr_leg"/>
  <child link="${prefix}fr_foot"/>
  <axis xyz="-4e-06 -1.0 0.000781"/>
</joint>

<joint name="${prefix}rr_i_hip" type="revolute">
  <origin xyz="0.043361 0.136421 0.100655" rpy="0.0 -0.0 0.0"/>
  <parent link="${prefix}base_link"/>
  <child link="${prefix}rr_hip"/>
  <axis xyz="0.999943 4e-06 0.010677"/>
  <limit upper="0.698132" lower="-0.436332" effort="100" velocity="100"/>
</joint>

<joint name="${prefix}rr_o_hip" type="revolute">
  <origin xyz="0.025609 -0.024389 -0.010823" rpy="0.0 -0.0 0.0"/>
  <parent link="${prefix}rr_hip"/>
  <child link="${prefix}rr_leg"/>
  <axis xyz="-4e-06 -1.0 0.000781"/>
  <limit upper="0.785398" lower="-0.785398" effort="100" velocity="100"/>
</joint>

<joint name="${prefix}rr_knee" type="revolute">
  <origin xyz="0.015613 -0.002284 -0.107499" rpy="0.0 -0.0 0.0"/>
  <parent link="${prefix}rr_leg"/>
  <child link="${prefix}rr_foot"/>
  <axis xyz="-4e-06 -1.0 0.000781"/>
  <limit upper="0.785398" lower="-0.785398" effort="100" velocity="100"/>
</joint>

<joint name="${prefix}fl_i_hip" type="revolute">
  <origin xyz="0.279969 0.214395 0.101949" rpy="0.0 -0.0 0.0"/>
  <parent link="${prefix}base_link"/>
  <child link="${prefix}fl_hip"/>
  <axis xyz="-0.999943 -4e-06 -0.010677"/>
  <limit upper="0.698132" lower="-0.436332" effort="100" velocity="100"/>
</joint>

<joint name="${prefix}rl_i_hip" type="revolute">
  <origin xyz="0.043361 0.214395 0.100634" rpy="0.0 -0.0 0.0"/>
  <parent link="${prefix}base_link"/>
  <child link="${prefix}rl_hip"/>
  <axis xyz="0.999943 4e-06 0.010677"/>
  <limit upper="0.698132" lower="-0.436332" effort="100" velocity="100"/>
</joint>

<joint name="${prefix}fl_o_hip" type="revolute">
  <origin xyz="-0.025359 0.024371 -0.011405" rpy="0.0 -0.0 0.0"/>
  <parent link="${prefix}fl_hip"/>
  <child link="${prefix}fl_leg"/>
  <axis xyz="4e-06 1.0 -0.000781"/>
  <limit upper="0.785398" lower="-0.785398" effort="100" velocity="100"/>
</joint>

<joint name="${prefix}rl_o_hip" type="revolute">
  <origin xyz="0.026136 0.027197 -0.01083" rpy="0.0 -0.0 0.0"/>
  <parent link="${prefix}rl_hip"/>
  <child link="${prefix}rl_leg"/>
  <axis xyz="4e-06 1.0 -0.000781"/>
  <limit upper="0.785398" lower="-0.785398" effort="100" velocity="100"/>
</joint>

<joint name="${prefix}fl_knee" type="revolute">
  <origin xyz="0.016571 0.002116 -0.107189" rpy="0.0 -0.0 0.0"/>
  <parent link="${prefix}fl_leg"/>
  <child link="${prefix}fl_foot"/>
  <axis xyz="4e-06 1.0 -0.000781"/>
  <limit upper="0.785398" lower="-0.785398" effort="100" velocity="100"/>
</joint>

<joint name="${prefix}rl_knee" type="revolute">
  <origin xyz="0.016571 0.002116 -0.107189" rpy="0.0 -0.0 0.0"/>
  <parent link="${prefix}rl_leg"/>
  <child link="${prefix}rl_foot"/>
  <axis xyz="4e-06 1.0 -0.000781"/>
  <limit upper="0.785398" lower="-0.785398" effort="100" velocity="100"/>
</joint>

<joint name="${prefix}fr_i_hip" type="revolute">
  <origin xyz="0.27656 0.136395 0.101973" rpy="0.0 -0.0 0.0"/>
  <parent link="${prefix}base_link"/>
  <child link="${prefix}fr_hip"/>
  <axis xyz="-0.999943 -4e-06 -0.010677"/>
  <limit upper="0.698132" lower="-0.349066" effort="100" velocity="100"/>
</joint>

</xacro:macro>
</robot>
