<?xml version="1.0" ?>
<robot name="quadruped" xmlns:xacro="http://www.ros.org/wiki/xacro">

<!-- Defined locally so Robot Developer Extensions can preview this file standalone. -->
<material name="quadruped_silver">
  <color rgba="0.700 0.700 0.700 1.000"/>
</material>

<xacro:macro name="quadruped" params="prefix">

<link name="${prefix}base_link">
  <visual>
    <origin xyz="0 0 0" rpy="0 0 0"/>
    <geometry>
      <mesh filename="package://quadruped_description/meshes/base_link.stl" scale="0.001 0.001 0.001"/>
    </geometry>
    <material name="quadruped_silver"/>
  </visual>
  <collision>
    <origin xyz="0 0 0" rpy="0 0 0"/>
    <geometry>
      <mesh filename="package://quadruped_description/meshes/base_link.stl" scale="0.001 0.001 0.001"/>
    </geometry>
  </collision>
</link>

<link name="${prefix}fr_leg">
  <inertial>
    <origin xyz="-0.10906884131921281 0.030259656327212947 0.05925371268468506" rpy="0 0 0"/>
    <mass value="0.8819417369199037"/>
    <inertia ixx="0.001238" iyy="0.001149" izz="0.000203" ixy="2e-06" iyz="4.9e-05" ixz="-1.1e-05"/>
  </inertial>
  <visual>
    <origin xyz="0 0 0" rpy="0 0 0"/>
    <geometry>
      <mesh filename="package://quadruped_description/meshes/fr_leg.stl" scale="0.001 0.001 0.001"/>
    </geometry>
    <material name="quadruped_silver"/>
  </visual>
  <collision>
    <origin xyz="0 0 0" rpy="0 0 0"/>
    <geometry>
      <mesh filename="package://quadruped_description/meshes/fr_leg.stl" scale="0.001 0.001 0.001"/>
    </geometry>
  </collision>
</link>

<link name="${prefix}fr_foot">
  <inertial>
    <origin xyz="-0.07965730267671656 0.05211105869003481 0.053051360543432624" rpy="0 0 0"/>
    <mass value="0.4701549157206577"/>
    <inertia ixx="0.00096" iyy="0.000946" izz="7e-05" ixy="-3e-06" iyz="-1.6e-05" ixz="-1.7e-05"/>
  </inertial>
  <visual>
    <origin xyz="0 0 0" rpy="0 0 0"/>
    <geometry>
      <mesh filename="package://quadruped_description/meshes/fr_foot.stl" scale="0.001 0.001 0.001"/>
    </geometry>
    <material name="quadruped_silver"/>
  </visual>
  <collision>
    <origin xyz="0 0 0" rpy="0 0 0"/>
    <geometry>
      <mesh filename="package://quadruped_description/meshes/fr_foot.stl" scale="0.001 0.001 0.001"/>
    </geometry>
  </collision>
</link>

<link name="${prefix}rr_hip">
  <inertial>
    <origin xyz="-0.02567584292474462 0.0057985296287781235 -0.010984130313089785" rpy="0 0 0"/>
    <mass value="0.43930544603172716"/>
    <inertia ixx="0.000129" iyy="0.000144" izz="9.8e-05" ixy="1e-06" iyz="0.0" ixz="-1e-06"/>
  </inertial>
  <visual>
    <origin xyz="0 0 0" rpy="0 0 0"/>
    <geometry>
      <mesh filename="package://quadruped_description/meshes/rr_hip.stl" scale="0.001 0.001 0.001"/>
    </geometry>
    <material name="quadruped_silver"/>
  </visual>
  <collision>
    <origin xyz="0 0 0" rpy="0 0 0"/>
    <geometry>
      <mesh filename="package://quadruped_description/meshes/rr_hip.stl" scale="0.001 0.001 0.001"/>
    </geometry>
  </collision>
</link>

<link name="${prefix}rr_leg">
  <inertial>
    <origin xyz="0.12413176830355416 0.030233497143917425 0.060425824110275216" rpy="0 0 0"/>
    <mass value="0.8819417369199037"/>
    <inertia ixx="0.001238" iyy="0.001149" izz="0.000203" ixy="2e-06" iyz="4.9e-05" ixz="-1.1e-05"/>
  </inertial>
  <visual>
    <origin xyz="0 0 0" rpy="0 0 0"/>
    <geometry>
      <mesh filename="package://quadruped_description/meshes/rr_leg.stl" scale="0.001 0.001 0.001"/>
    </geometry>
    <material name="quadruped_silver"/>
  </visual>
  <collision>
    <origin xyz="0 0 0" rpy="0 0 0"/>
    <geometry>
      <mesh filename="package://quadruped_description/meshes/rr_leg.stl" scale="0.001 0.001 0.001"/>
    </geometry>
  </collision>
</link>

<link name="${prefix}rr_foot">
  <inertial>
    <origin xyz="0.10204451493294936 0.04925989950673911 0.054195813866881604" rpy="0 0 0"/>
    <mass value="0.4701549157206577"/>
    <inertia ixx="0.00096" iyy="0.000946" izz="7e-05" ixy="-3e-06" iyz="-1.6e-05" ixz="-1.7e-05"/>
  </inertial>
  <visual>
    <origin xyz="0 0 0" rpy="0 0 0"/>
    <geometry>
      <mesh filename="package://quadruped_description/meshes/rr_foot.stl" scale="0.001 0.001 0.001"/>
    </geometry>
    <material name="quadruped_silver"/>
  </visual>
  <collision>
    <origin xyz="0 0 0" rpy="0 0 0"/>
    <geometry>
      <mesh filename="package://quadruped_description/meshes/rr_foot.stl" scale="0.001 0.001 0.001"/>
    </geometry>
  </collision>
</link>

<link name="${prefix}fl_hip">
  <inertial>
    <origin xyz="0.025675691118024063 -0.005798117771108016 -0.01098425102162165" rpy="0 0 0"/>
    <mass value="0.43930544603256694"/>
    <inertia ixx="0.000129" iyy="0.000144" izz="9.8e-05" ixy="1e-06" iyz="-0.0" ixz="1e-06"/>
  </inertial>
  <visual>
    <origin xyz="0 0 0" rpy="0 0 0"/>
    <geometry>
      <mesh filename="package://quadruped_description/meshes/fl_hip.stl" scale="0.001 0.001 0.001"/>
    </geometry>
    <material name="quadruped_silver"/>
  </visual>
  <collision>
    <origin xyz="0 0 0" rpy="0 0 0"/>
    <geometry>
      <mesh filename="package://quadruped_description/meshes/fl_hip.stl" scale="0.001 0.001 0.001"/>
    </geometry>
  </collision>
</link>

<link name="${prefix}rl_hip">
  <inertial>
    <origin xyz="-0.0262064082774935 -0.005858538546221509 -0.011000587494152933" rpy="0 0 0"/>
    <mass value="0.44027574194204244"/>
    <inertia ixx="0.000129" iyy="0.000143" izz="9.8e-05" ixy="-1e-06" iyz="-0.0" ixz="-1e-06"/>
  </inertial>
  <visual>
    <origin xyz="0 0 0" rpy="0 0 0"/>
    <geometry>
      <mesh filename="package://quadruped_description/meshes/rl_hip.stl" scale="0.001 0.001 0.001"/>
    </geometry>
    <material name="quadruped_silver"/>
  </visual>
  <collision>
    <origin xyz="0 0 0" rpy="0 0 0"/>
    <geometry>
      <mesh filename="package://quadruped_description/meshes/rl_hip.stl" scale="0.001 0.001 0.001"/>
    </geometry>
  </collision>
</link>

<link name="${prefix}fl_leg">
  <inertial>
    <origin xyz="-0.11279153350593375 -0.10145749196420971 0.059059127554266164" rpy="0 0 0"/>
    <mass value="0.8798800717218304"/>
    <inertia ixx="0.001231" iyy="0.001145" izz="0.000199" ixy="-4e-06" iyz="-4.8e-05" ixz="-1.7e-05"/>
  </inertial>
  <visual>
    <origin xyz="0 0 0" rpy="0 0 0"/>
    <geometry>
      <mesh filename="package://quadruped_description/meshes/fl_leg.stl" scale="0.001 0.001 0.001"/>
    </geometry>
    <material name="quadruped_silver"/>
  </visual>
  <collision>
    <origin xyz="0 0 0" rpy="0 0 0"/>
    <geometry>
      <mesh filename="package://quadruped_description/meshes/fl_leg.stl" scale="0.001 0.001 0.001"/>
    </geometry>
  </collision>
</link>

<link name="${prefix}rl_leg">
  <inertial>
    <origin xyz="0.12381679155567626 -0.10145777194327846 0.06027044245550504" rpy="0 0 0"/>
    <mass value="0.8798800717218304"/>
    <inertia ixx="0.001231" iyy="0.001145" izz="0.000199" ixy="-4e-06" iyz="-4.8e-05" ixz="-1.7e-05"/>
  </inertial>
  <visual>
    <origin xyz="0 0 0" rpy="0 0 0"/>
    <geometry>
      <mesh filename="package://quadruped_description/meshes/rl_leg.stl" scale="0.001 0.001 0.001"/>
    </geometry>
    <material name="quadruped_silver"/>
  </visual>
  <collision>
    <origin xyz="0 0 0" rpy="0 0 0"/>
    <geometry>
      <mesh filename="package://quadruped_description/meshes/rl_leg.stl" scale="0.001 0.001 0.001"/>
    </geometry>
  </collision>
</link>

<link name="${prefix}fl_foot">
  <inertial>
    <origin xyz="-0.08357027206670639 -0.12078267430778301 0.05309912453495626" rpy="0 0 0"/>
    <mass value="0.4874391356623863"/>
    <inertia ixx="0.000995" iyy="0.00098" izz="7.3e-05" ixy="3e-06" iyz="1.9e-05" ixz="-1.8e-05"/>
  </inertial>
  <visual>
    <origin xyz="0 0 0" rpy="0 0 0"/>
    <geometry>
      <mesh filename="package://quadruped_description/meshes/fl_foot.stl" scale="0.001 0.001 0.001"/>
    </geometry>
    <material name="quadruped_silver"/>
  </visual>
  <collision>
    <origin xyz="0 0 0" rpy="0 0 0"/>
    <geometry>
      <mesh filename="package://quadruped_description/meshes/fl_foot.stl" scale="0.001 0.001 0.001"/>
    </geometry>
  </collision>
</link>

<link name="${prefix}rl_foot">
  <inertial>
    <origin xyz="0.10154005299490362 -0.12360795428685169 0.054338439436195096" rpy="0 0 0"/>
    <mass value="0.4874391356623863"/>
    <inertia ixx="0.000995" iyy="0.00098" izz="7.3e-05" ixy="3e-06" iyz="1.9e-05" ixz="-1.8e-05"/>
  </inertial>
  <visual>
    <origin xyz="0 0 0" rpy="0 0 0"/>
    <geometry>
      <mesh filename="package://quadruped_description/meshes/rl_foot.stl" scale="0.001 0.001 0.001"/>
    </geometry>
    <material name="quadruped_silver"/>
  </visual>
  <collision>
    <origin xyz="0 0 0" rpy="0 0 0"/>
    <geometry>
      <mesh filename="package://quadruped_description/meshes/rl_foot.stl" scale="0.001 0.001 0.001"/>
    </geometry>
  </collision>
</link>

<link name="${prefix}fr_hip">
  <inertial>
    <origin xyz="0.026205971909705736 0.00585882960814103 -0.01100089311243034" rpy="0 0 0"/>
    <mass value="0.4402757419432759"/>
    <inertia ixx="0.000129" iyy="0.000143" izz="9.8e-05" ixy="-1e-06" iyz="0.0" ixz="1e-06"/>
  </inertial>
  <visual>
    <origin xyz="0 0 0" rpy="0 0 0"/>
    <geometry>
      <mesh filename="package://quadruped_description/meshes/fr_hip.stl" scale="0.001 0.001 0.001"/>
    </geometry>
    <material name="quadruped_silver"/>
  </visual>
  <collision>
    <origin xyz="0 0 0" rpy="0 0 0"/>
    <geometry>
      <mesh filename="package://quadruped_description/meshes/fr_hip.stl" scale="0.001 0.001 0.001"/>
    </geometry>
  </collision>
</link>

<joint name="${prefix}fr_o_hip" type="revolute">
  <origin xyz="0.026007 0.027205 -0.011087" rpy="0.0 -0.0 0.0"/>
  <parent link="${prefix}fr_hip"/>
  <child link="${prefix}fr_leg"/>
  <axis xyz="-0.0 1.0 0.0"/>
  <limit upper="0.785398" lower="-0.785398" effort="100" velocity="100"/>
</joint>

<joint name="${prefix}fr_knee" type="continuous">
  <origin xyz="-0.01513 0.0022 -0.107733" rpy="0.0 -0.0 0.0"/>
  <parent link="${prefix}fr_leg"/>
  <child link="${prefix}fr_foot"/>
  <axis xyz="0.0 1.0 0.0"/>
</joint>

<joint name="${prefix}rr_i_hip" type="revolute">
  <origin xyz="0.126603 0.003421 0.101152" rpy="0.0 -0.0 0.0"/>
  <parent link="${prefix}base_link"/>
  <child link="${prefix}rr_hip"/>
  <axis xyz="-1.0 -0.0 -0.0"/>
  <limit upper="0.698132" lower="-0.436332" effort="100" velocity="100"/>
</joint>

<joint name="${prefix}rr_o_hip" type="revolute">
  <origin xyz="-0.025492 0.02438 -0.011115" rpy="0.0 -0.0 0.0"/>
  <parent link="${prefix}rr_hip"/>
  <child link="${prefix}rr_leg"/>
  <axis xyz="0.0 1.0 0.0"/>
  <limit upper="0.785398" lower="-0.785398" effort="100" velocity="100"/>
</joint>

<joint name="${prefix}rr_knee" type="revolute">
  <origin xyz="-0.014464 0.0022 -0.107661" rpy="0.0 -0.0 0.0"/>
  <parent link="${prefix}rr_leg"/>
  <child link="${prefix}rr_foot"/>
  <axis xyz="0.0 1.0 0.0"/>
  <limit upper="0.785398" lower="-0.785398" effort="100" velocity="100"/>
</joint>

<joint name="${prefix}fl_i_hip" type="revolute">
  <origin xyz="-0.110006 -0.074553 0.09998" rpy="0.0 -0.0 0.0"/>
  <parent link="${prefix}base_link"/>
  <child link="${prefix}fl_hip"/>
  <axis xyz="1.0 0.0 0.0"/>
  <limit upper="0.698132" lower="-0.436332" effort="100" velocity="100"/>
</joint>

<joint name="${prefix}rl_i_hip" type="revolute">
  <origin xyz="0.126603 -0.074553 0.101191" rpy="0.0 -0.0 0.0"/>
  <parent link="${prefix}base_link"/>
  <child link="${prefix}rl_hip"/>
  <axis xyz="-1.0 -0.0 -0.0"/>
  <limit upper="0.698132" lower="-0.436332" effort="100" velocity="100"/>
</joint>

<joint name="${prefix}fl_o_hip" type="revolute">
  <origin xyz="0.025479 -0.02438 -0.011115" rpy="0.0 -0.0 0.0"/>
  <parent link="${prefix}fl_hip"/>
  <child link="${prefix}fl_leg"/>
  <axis xyz="0.0 -1.0 -0.0"/>
  <limit upper="0.785398" lower="-0.785398" effort="100" velocity="100"/>
</joint>

<joint name="${prefix}rl_o_hip" type="revolute">
  <origin xyz="-0.026019 -0.027205 -0.011087" rpy="0.0 -0.0 0.0"/>
  <parent link="${prefix}rl_hip"/>
  <child link="${prefix}rl_leg"/>
  <axis xyz="0.0 -1.0 -0.0"/>
  <limit upper="0.785398" lower="-0.785398" effort="100" velocity="100"/>
</joint>

<joint name="${prefix}fl_knee" type="revolute">
  <origin xyz="-0.015425 -0.0022 -0.107358" rpy="0.0 -0.0 0.0"/>
  <parent link="${prefix}fl_leg"/>
  <child link="${prefix}fl_foot"/>
  <axis xyz="0.0 -1.0 -0.0"/>
  <limit upper="0.785398" lower="-0.785398" effort="100" velocity="100"/>
</joint>

<joint name="${prefix}rl_knee" type="revolute">
  <origin xyz="-0.015425 -0.0022 -0.107358" rpy="0.0 -0.0 0.0"/>
  <parent link="${prefix}rl_leg"/>
  <child link="${prefix}rl_foot"/>
  <axis xyz="0.0 -1.0 -0.0"/>
  <limit upper="0.785398" lower="-0.785398" effort="100" velocity="100"/>
</joint>

<joint name="${prefix}fr_i_hip" type="revolute">
  <origin xyz="-0.106597 0.003447 0.09998" rpy="0.0 -0.0 0.0"/>
  <parent link="${prefix}base_link"/>
  <child link="${prefix}fr_hip"/>
  <axis xyz="1.0 0.0 0.0"/>
  <limit upper="0.698132" lower="-0.349066" effort="100" velocity="100"/>
</joint>

</xacro:macro>

<xacro:quadruped prefix="" />
</robot>
